<?xml version="1.0" encoding="utf-8" ?>
<!-- This URDF was automatically created by SolidWorks to URDF Exporter! Originally created by Stephen Brawner (brawner@gmail.com) 
     Commit Version: 1.6.0-4-g7f85cfe  Build Version: 1.6.7995.38578
     For more information, please see http://wiki.ros.org/sw_urdf_exporter -->
<robot name="robot_arm_jj_v4">
    <link name="base_link">
        <inertial>
            <origin xyz="2.63906858121947E-07 0.0123548014896462 0.0180317042798397" rpy="0 0 0" />
            <mass value="0.145711251346503" />
            <inertia ixx="8.89769342658515E-05" ixy="-7.51213869489288E-10" ixz="-1.26120262751118E-09" iyy="6.08855228440413E-05" iyz="3.4524251535453E-07" izz="0.000109831670457128" />
        </inertial>
        <visual>
            <origin xyz="0 0 0" rpy="0 0 0" />
            <geometry>
                <mesh filename="package://robot_arm_jj_v4/meshes/base_link.STL" />
            </geometry>
            <material name="">
                <color rgba="0.792156862745098 0.819607843137255 0.933333333333333 1" />
            </material>
        </visual>
        <collision>
            <origin xyz="0 0 0" rpy="0 0 0" />
            <geometry>
                <mesh filename="package://robot_arm_jj_v4/meshes/base_link.STL" />
            </geometry>
        </collision>
    </link>
    <link name="link_1">
        <inertial>
            <origin xyz="0.000941265209741439 -2.05725101131475E-06 0.0268715106739904" rpy="0 0 0" />
            <mass value="0.0460049636465042" />
            <inertia ixx="1.01749219185809E-05" ixy="1.26107333601568E-09" ixz="1.96531067765913E-07" iyy="1.19487278016208E-05" iyz="-6.23099772368389E-10" izz="6.92576650304568E-06" />
        </inertial>
        <visual>
            <origin xyz="0 0 0" rpy="0 0 0" />
            <geometry>
                <mesh filename="package://robot_arm_jj_v4/meshes/link_1.STL" />
            </geometry>
            <material name="">
                <color rgba="0.792156862745098 0.819607843137255 0.933333333333333 1" />
            </material>
        </visual>
        <collision>
            <origin xyz="0 0 0" rpy="0 0 0" />
            <geometry>
                <mesh filename="package://robot_arm_jj_v4/meshes/link_1.STL" />
            </geometry>
        </collision>
    </link>
    <joint name="joint_1" type="revolute">
        <origin xyz="0 0 0.04188" rpy="0 0 0" />
        <parent link="base_link" />
        <child link="link_1" />
        <axis xyz="0 0 -1" />
        <limit lower="-2.16" upper="2.16" effort="1.5" velocity="3.08" />
    </joint>
    <link name="link_2">
        <inertial>
            <origin xyz="-0.00020674 0.00036306 0.042749" rpy="0 0 0" />
            <mass value="0.021327" />
            <inertia ixx="6.4724E-06" ixy="-8.8958E-12" ixz="2.2787E-11" iyy="1.2466E-05" iyz="-7.9921E-08" izz="8.893E-06" />
        </inertial>
        <visual>
            <origin xyz="0 0 0" rpy="0 0 0" />
            <geometry>
                <mesh filename="package://robot_arm_jj_v4/meshes/link_2.STL" />
            </geometry>
            <material name="">
                <color rgba="0.79216 0.81961 0.93333 1" />
            </material>
        </visual>
        <collision>
            <origin xyz="0 0 0" rpy="0 0 0" />
            <geometry>
                <mesh filename="package://robot_arm_jj_v4/meshes/link_2.STL" />
            </geometry>
        </collision>
    </link>
    <joint name="joint_2" type="revolute">
        <origin xyz="-0.00055 0 0.0415" rpy="0 0 0" />
        <parent link="link_1" />
        <child link="link_2" />
        <axis xyz="-1 0 0" />
        <limit lower="-2.16" upper="2.16" effort="1.5" velocity="3.08" />
    </joint>
    <link name="link_3">
        <inertial>
            <origin xyz="0.00102928995198108 -1.21839792428321E-06 0.0297373962553241" rpy="0 0 0" />
            <mass value="0.0647095833170316" />
            <inertia ixx="1.28329399907313E-05" ixy="6.23266432613802E-13" ixz="-3.27231100223613E-08" iyy="1.613591036666E-05" iyz="9.86813823573687E-12" izz="1.06295802345988E-05" />
        </inertial>
        <visual>
            <origin xyz="0 0 0" rpy="0 0 0" />
            <geometry>
                <mesh filename="package://robot_arm_jj_v4/meshes/link_3.STL" />
            </geometry>
            <material name="">
                <color rgba="0.792156862745098 0.819607843137255 0.933333333333333 1" />
            </material>
        </visual>
        <collision>
            <origin xyz="0 0 0" rpy="0 0 0" />
            <geometry>
                <mesh filename="package://robot_arm_jj_v4/meshes/link_3.STL" />
            </geometry>
        </collision>
    </link>
    <joint name="joint_3" type="revolute">
        <origin xyz="0 0 0.078" rpy="0 0 0" />
        <parent link="link_2" />
        <child link="link_3" />
        <axis xyz="1 0 0" />
        <limit lower="-2.16" upper="2.16" effort="1.5" velocity="3.08" />
    </joint>
    <link name="link_4">
        <inertial>
            <origin xyz="0.0014758 -0.013313 0.001152" rpy="0 0 0" />
            <mass value="0.046211" />
            <inertia ixx="1.0173E-05" ixy="3.2723E-08" ixz="6.3531E-13" iyy="4.0373E-06" iyz="1.1825E-10" izz="9.3659E-06" />
        </inertial>
        <visual>
            <origin xyz="0 0 0" rpy="0 0 0" />
            <geometry>
                <mesh filename="package://robot_arm_jj_v4/meshes/link_4.STL" />
            </geometry>
            <material name="">
                <color rgba="0.79216 0.81961 0.93333 1" />
            </material>
        </visual>
        <collision>
            <origin xyz="0 0 0" rpy="0 0 0" />
            <geometry>
                <mesh filename="package://robot_arm_jj_v4/meshes/link_4.STL" />
            </geometry>
        </collision>
    </link>
    <joint name="joint_4" type="revolute">
        <origin xyz="-0.0002 0 0.099" rpy="0 0 0" />
        <parent link="link_3" />
        <child link="link_4" />
        <axis xyz="1 0 0" />
        <limit lower="-2.16" upper="2.16" effort="1.5" velocity="3.08" />
    </joint>
    <link name="link_5">
        <inertial>
            <origin xyz="-0.00042263 -0.025719 -0.00049055" rpy="0 0 0" />
            <mass value="0.061237" />
            <inertia ixx="1.2088E-05" ixy="-1.374E-10" ixz="-1.3197E-12" iyy="5.4197E-06" iyz="-2.2591E-07" izz="1.3437E-05" />
        </inertial>
        <visual>
            <origin xyz="0 0 0" rpy="0 0 0" />
            <geometry>
                <mesh filename="package://robot_arm_jj_v4/meshes/link_5.STL" />
            </geometry>
            <material name="">
                <color rgba="0.79216 0.81961 0.93333 1" />
            </material>
        </visual>
        <collision>
            <origin xyz="0 0 0" rpy="0 0 0" />
            <geometry>
                <mesh filename="package://robot_arm_jj_v4/meshes/link_5.STL" />
            </geometry>
        </collision>
    </link>
    <joint name="joint_5" type="revolute">
        <origin xyz="0.00075 -0.02275 0.0389" rpy="0 0 0" />
        <parent link="link_4" />
        <child link="link_5" />
        <axis xyz="0 0 -1" />
        <limit lower="-2.16" upper="2.16" effort="1.5" velocity="3.08" />
    </joint>
    <transmission name="trans_joint_1">
        <type>transmission_interface/SimpleTransmission</type>
        <joint name="joint_1">
            <hardwareInterface>hardware_interface/EffortJointInterface</hardwareInterface>
        </joint>
        <actuator name="joint_1_motor">
            <hardwareInterface>hardware_interface/EffortJointInterface</hardwareInterface>
            <mechanicalReduction>1</mechanicalReduction>
        </actuator>
    </transmission>
    <transmission name="trans_joint_2">
        <type>transmission_interface/SimpleTransmission</type>
        <joint name="joint_2">
            <hardwareInterface>hardware_interface/EffortJointInterface</hardwareInterface>
        </joint>
        <actuator name="joint_2_motor">
            <hardwareInterface>hardware_interface/EffortJointInterface</hardwareInterface>
            <mechanicalReduction>1</mechanicalReduction>
        </actuator>
    </transmission>
    <transmission name="trans_joint_3">
        <type>transmission_interface/SimpleTransmission</type>
        <joint name="joint_3">
            <hardwareInterface>hardware_interface/EffortJointInterface</hardwareInterface>
        </joint>
        <actuator name="joint_3_motor">
            <hardwareInterface>hardware_interface/EffortJointInterface</hardwareInterface>
            <mechanicalReduction>1</mechanicalReduction>
        </actuator>
    </transmission>
    <transmission name="trans_joint_4">
        <type>transmission_interface/SimpleTransmission</type>
        <joint name="joint_4">
            <hardwareInterface>hardware_interface/EffortJointInterface</hardwareInterface>
        </joint>
        <actuator name="joint_4_motor">
            <hardwareInterface>hardware_interface/EffortJointInterface</hardwareInterface>
            <mechanicalReduction>1</mechanicalReduction>
        </actuator>
    </transmission>
    <transmission name="trans_joint_5">
        <type>transmission_interface/SimpleTransmission</type>
        <joint name="joint_5">
            <hardwareInterface>hardware_interface/EffortJointInterface</hardwareInterface>
        </joint>
        <actuator name="joint_5_motor">
            <hardwareInterface>hardware_interface/EffortJointInterface</hardwareInterface>
            <mechanicalReduction>1</mechanicalReduction>
        </actuator>
    </transmission>
    <gazebo>
        <plugin name="gazebo_ros_control">
            <robotNamespace>/</robotNamespace>
        </plugin>
    </gazebo>
</robot>

